Workbook

Sheet 测试集
A1: 编号 | B1: 分组 | C1: 对话内容 | D1: 标准答案 | E1: 违规类型 | F1: 依据条文 | G1: 风格 | H1: 是否难题 | I1: 考点说明 | J1: Agent判断(结论) | K1: Agent判断(类型) | L1: 是否判对 | M1: 错误归因 | N1: 备注
A2: R1-01 | B2: 前30 | C2: 顾客：昨天收到的连衣裙，不喜欢，想七天无理由退货。 客服：这款是特价款，特价商品不支持退换哦。 顾客：下单页面没看到写不能退啊。 客服：特价款都是这样的，没法退。 | D2: 违规 | E2: R1 | F2: 《暂行办法》第六条、第七条、第二十条；《保护法》第二十五条 | G2: 直白 | I2: 特价不是法定例外，购买时也没有确认过 | J2: 违规 | K2: R1 | L2: =IF(J2="","",IF(AND(J2=D2,IF(K2="无","",K2)=IF(E2="","",E2)),"对","错")) -> 对
A3: R1-02 | B3: 前30 | C3: 顾客：保温杯收到第二天，想退。 客服：您下单时勾选了“本商品不支持七天无理由退货”，不能退。 顾客：我没主动勾，页面本来就打好了。 客服：是默认勾上的，但您没取消就算同意。 | D3: 违规 | E3: R1 | F3: 《实施条例》第十九条第二款；《暂行办法》第二十条 | G3: 直白 | I3: 把默认勾选当作消费者确认 | J3: 违规 | K3: R1 | L3: =IF(J3="","",IF(AND(J3=D3,IF(K3="无","",K3)=IF(E3="","",E3)),"对","错")) -> 对
A4: R1-03 | B4: 前30 | C4: 顾客：台灯收到三天，我只是拆开通电试了下亮不亮，没用过，想退。 客服：您已经拆封通电，影响二次销售，不能退了。 顾客：我只是确认能不能用啊。 客服：拆了就不退，这是规定。 | D4: 违规 | E4: R1 | F4: 《暂行办法》第八条、第三十一条第（一）项；《实施条例》第十九条第三款 | G4: 直白 | I4: 为查验、合理调试而拆封，不影响商品完好 | J4: 违规 | K4: R1 | L4: =IF(J4="","",IF(AND(J4=D4,IF(K4="无","",K4)=IF(E4="","",E4)),"对","错")) -> 对
A5: R1-04 | B5: 前30 | C5: 顾客：我10月10日签收的水杯，想申请无理由退货。 客服：您今天申请是10月17日，超过七天了，不能退。 顾客：10月10日签收，今天不是第七天吗？ 客服：七天从签收当天算，今天是第八天，超了。 | D5: 违规 | E5: R1 | F5: 《暂行办法》第十条 | G5: 直白 | I5: 七日自签收次日起算：10月11日为第1天，10月17日为第7天，仍在期内 | J5: 违规 | K5: R1 | L5: =IF(J5="","",IF(AND(J5=D5,IF(K5="无","",K5)=IF(E5="","",E5)),"对","错")) -> 对
A6: R1-05 | B6: 后10 | C6: 顾客：运动鞋收到五天，尺码不合适，鞋子没穿过，想无理由退货。 客服：鞋子有质量问题吗？ 顾客：没有，就是不合适。 客服：没有质量问题的话，我们不支持退货。 | D6: 违规 | E6: R1 | F6: 《保护法》第二十五条第一款 | G6: 直白 | I6: 无理由退货无需说明理由 | J6: 违规 | K6: R1 | L6: =IF(J6="","",IF(AND(J6=D6,IF(K6="无","",K6)=IF(E6="","",E6)),"对","错")) -> 对
A7: R2-01 | B7: 前30 | C7: 顾客：我是敏感肌，这款面霜会过敏吗？ 客服：放心，我们这款绝对不会过敏，百分百安全。 顾客：真的所有人都不会吗？ 客服：对，不管什么肤质都没问题，您直接用就行。 | D7: 违规 | E7: R2 | F7: 《保护法》第二十条第一款、第五十六条第一款第（六）项 | G7: 直白 | I7: 对安全性作绝对化承诺 | J7: 违规 | K7: R2 | L7: =IF(J7="","",IF(AND(J7=D7,IF(K7="无","",K7)=IF(E7="","",E7)),"对","错")) -> 对
A8: R2-02 | B8: 前30 | C8: 顾客：我脖子疼了好几年，这个按摩仪有用吗？ 客服：有用的，这款能根治颈椎病，用一个月就不用再去医院了。 顾客：真的能治好？ 客服：能，好多顾客都是这样治好的。 | D8: 违规 | E8: R2 | F8: 《实施条例》第十五条；《保护法》第二十条第一款 | G8: 直白 | I8: 虚构、夸大治疗功效 | J8: 违规 | K8: R2 | L8: =IF(J8="","",IF(AND(J8=D8,IF(K8="无","",K8)=IF(E8="","",E8)),"对","错")) -> 对
A9: R2-03 | B9: 前30 | C9: 顾客：电饭煲收到有点担心质量，坏了怎么办？ 客服：您放心，坏了我们三天内上门免费维修。 （五天后） 顾客：电饭煲坏了，你们说好上门修的。 客服：我们其实没有上门维修服务，当时是为了让您下单才这么说的。 | D9: 违规 | E9: R2 | F9: 《实施条例》第十二条；《保护法》第二十条第一款 | G9: 直白 | I9: 作出售后承诺，且对话里明确承认不打算兑现 | J9: 违规 | K9: R2 | L9: =IF(J9="","",IF(AND(J9=D9,IF(K9="无","",K9)=IF(E9="","",E9)),"对","错")) -> 对
A10: R2-04 | B10: 后10 | C10: 顾客：我痘痘很严重，这个祛痘精华能好吗？ 客服：保证有效，用一周痘痘肯定全部消掉。 顾客：万一没效果呢？ 客服：不会没效果的，您放心用。 | D10: 违规 | E10: R2 | F10: 《保护法》第二十条第一款、第五十六条第一款第（六）项 | G10: 直白 | I10: 对功效作“保证有效”式承诺 | J10: 违规 | K10: R2 | L10: =IF(J10="","",IF(AND(J10=D10,IF(K10="无","",K10)=IF(E10="","",E10)),"对","错")) -> 对
A11: R3-01 | B11: 前30 | C11: 顾客：电水壶收到第4天，一加热就漏水，我要退货。 客服：亲，抱歉～我们店质量问题7天内包退换的哦，这边先给您安排维修吧。 顾客：不是包退换吗？我不想修，想退。 客服：亲，维修是优先处理方式呢，暂时不支持直接退货哦～ | D11: 违规 | E11: R3 | F11: 《实施条例》第十二条；《保护法》第二十四条 | G11: 客气 | I11: 自己承诺7天包退换，却只给维修、拒绝退货 | J11: 违规 | K11: R3 | L11: =IF(J11="","",IF(AND(J11=D11,IF(K11="无","",K11)=IF(E11="","",E11)),"对","错")) -> 对
A12: R3-02 | B12: 前30 | C12: 顾客（10月9日）：无理由退货的商品寄回了，快递显示今天签收，什么时候退款？ 客服（10月9日）：亲，已收到，检查过商品完好，我们会尽快处理哦～ 顾客（10月20日）：都十多天了还没到账。 客服（10月20日）：亲，财务在处理中呢，请您再耐心等等～ 顾客（10月25日）：第十六天了。 客服（10月25日）：亲，理解您着急，我再帮您催一下哦～ | D12: 违规 | E12: R3 | F12: 《暂行办法》第十三条、第三十一条第（三）项 | G12: 客气 | I12: 不看是否故意：商品完好，10月9日收到退回商品，至10月25日为第16天，超过十五日未退款 | J12: 违规 | K12: R3 | L12: =IF(J12="","",IF(AND(J12=D12,IF(K12="无","",K12)=IF(E12="","",E12)),"对","错")) -> 对
A13: R3-03 | B13: 前30 | C13: 顾客：数据线用了4个月就坏了，页面写的质保2年。 客服：亲，我们这款质量问题7天包退换，15天包换新，90天内免费维修，超过90天只免费维修，运费自理哦～ 顾客：页面写的是2年啊。 客服：亲，以店铺售后规则为准呢，您寄回来我们帮您修，运费需要您承担哦～ | D13: 违规 | E13: R3 | F13: 《实施条例》第十二条；《保护法》第二十四条第二款 | G13: 客气 | I13: 与页面承诺不符，且让消费者承担质量问题的运费（情形改编自本人的真实购物经历） | J13: 违规 | K13: R3 | L13: =IF(J13="","",IF(AND(J13=D13,IF(K13="无","",K13)=IF(E13="","",E13)),"对","错")) -> 对
A14: R3-04 | B14: 后10 | C14: 顾客：耳机收到第3天，右耳没声音，质量问题，想退货。 客服：亲，可以退的哦～退回的运费需要您先自己承担一下呢。 顾客：质量问题的运费不该你们出吗？ 客服：亲，店铺规则是退货运费由买家承担，没办法的哦～ | D14: 违规 | E14: R3 | F14: 《保护法》第二十四条第二款 | G14: 客气 | I14: 让消费者承担质量问题的退货运费；与R3-03运费点相同，检验改进后能否举一反三 | J14: 违规 | K14: R3 | L14: =IF(J14="","",IF(AND(J14=D14,IF(K14="无","",K14)=IF(E14="","",E14)),"对","错")) -> 对
A15: R4-01 | B15: 前30 | C15: 顾客：我要退这个杯子，钱怎么退给我？ 客服：退款需要核实身份，请把您的身份证号、银行卡号和银行卡密码发给我。 顾客：密码也要吗？ 客服：要的，不然系统无法办理退款。 | D15: 违规 | E15: R4 | F15: 《保护法》第二十九条第一款；《实施条例》第二十三条 | G15: 直白 | I15: 退款原路返回，不需要银行卡密码 | L15: =IF(J15="","",IF(AND(J15=D15,IF(K15="无","",K15)=IF(E15="","",E15)),"对","错"))
A16: R4-02 | B16: 前30 | C16: 顾客：我想换个尺码，怎么操作？ 客服：亲，可以的呢～为了给您建立专属会员档案、方便后续享受优惠，麻烦提供一下您的身份证号码和工作单位哦。 顾客：换尺码也要这些吗？ 客服：建档之后换货会更快哦，不提供也行，不过换货可能会慢一些呢～ | D16: 违规 | E16: R4 | F16: 《实施条例》第二十三条；《保护法》第二十九条第一款 | G16: 客气 | I16: 语气客气，但以“建档”为由索要与换货无关的信息，还变相施压 | J16: 违规 | K16: R4 | L16: =IF(J16="","",IF(AND(J16=D16,IF(K16="无","",K16)=IF(E16="","",E16)),"对","错")) -> 对
A17: R4-03 | B17: 前30 | C17: 顾客：快递显示已签收，但我没收到，能帮我查一下吗？ 客服：好的，我帮您看下。订单信息给您核对：收件人张某某，电话138××××5678，地址××区××路12号，昨天16:20签收。 顾客：这不是我的名字和地址啊。 客服：不好意思，我调错订单了，这是另一位顾客的，您忽略就行。 | D17: 违规 | E17: R4 | F17: 《保护法》第二十九条第二款、第十四条、第五十条 | G17: 一般 | I17: 向消费者披露了另一位顾客的个人信息 | L17: =IF(J17="","",IF(AND(J17=D17,IF(K17="无","",K17)=IF(E17="","",E17)),"对","错"))
A18: R4-04 | B18: 后10 | C18: 顾客：手机收到不满意，申请退款。 客服：亲，这单金额比较大，为了保障您的资金安全，需要您上传一下身份证正反面照片核实身份哦～ 顾客：之前退款没要求过啊。 客服：大额订单都会核实的呢～ | D18: 违规 | E18: R4 | F18: 《实施条例》第二十三条第一款；《保护法》第二十九条第一款 | G18: 客气 | I18: 退款原路返回，用不到证件照（此题标准答案由本人判定） | J18: 待复核 | K18: R4 | L18: =IF(J18="","",IF(AND(J18=D18,IF(K18="无","",K18)=IF(E18="","",E18)),"对","错")) -> 错
A19: R5-01 | B19: 前30 | C19: 顾客：这是我第三次问了，退款到底什么时候到账？ 客服：我跟您说了三遍了，三到五个工作日，您是不是听不懂人话？ 顾客：你怎么说话的？ 客服：我说错了吗？脑子不好使就别网购。 | D19: 违规 | E19: R5 | F19: 《保护法》第十四条、第五十条、第五十六条第一款第（九）项 | G19: 直白 | I19: 辱骂、侮辱消费者 | J19: 违规 | K19: R5 | L19: =IF(J19="","",IF(AND(J19=D19,IF(K19="无","",K19)=IF(E19="","",E19)),"对","错")) -> 对
A20: R5-02 | B20: 前30 | C20: 顾客：这个优惠券我不知道怎么用，能教一下吗？ 客服：亲，这么简单的操作都不会，是不是平时不怎么用脑子呢～ 顾客：你什么意思？ 客服：没什么意思呀亲，我只是觉得您可能需要多练习一下哦～ | D20: 违规 | E20: R5 | F20: 《保护法》第十四条、第五十条、第五十六条第一款第（九）项 | G20: 客气 | I20: 语气客气，但讽刺、贬低消费者 | J20: 违规 | K20: R5 | L20: =IF(J20="","",IF(AND(J20=D20,IF(K20="无","",K20)=IF(E20="","",E20)),"对","错")) -> 对
A21: R5-03 | B21: 后10 | C21: 顾客：你们不处理的话，我要去平台投诉。 客服：你再投诉一个试试，我们店有的是办法让你好看。 顾客：你这是威胁我吗？ 客服：随你怎么理解，你自己掂量。 | D21: 违规 | E21: R5 | F21: 《保护法》第十四条、第五十条、第五十六条第一款第（九）项 | G21: 一般 | I21: 以“让你好看”威胁消费者 | J21: 违规 | K21: R5 | L21: =IF(J21="","",IF(AND(J21=D21,IF(K21="无","",K21)=IF(E21="","",E21)),"对","错")) -> 对
A22: 待R1-01 | B22: 前30 | C22: 顾客：内裤收到三天，拆开发现尺码小了，想退。 客服：贴身衣物拆封后影响卫生，下单页面有提示并要求确认的，不能退了。 顾客：我不记得点过什么确认。 客服：系统里有您的确认记录，不好意思。 | D22: 待复核 | E22: R1 | F22: 《暂行办法》第七条、第二十条第二款 | G22: 一般 | I22: 缺的信息：购买时是否确认过。对话里只有客服一面之词 | J22: 待复核 | K22: R1 | L22: =IF(J22="","",IF(AND(J22=D22,IF(K22="无","",K22)=IF(E22="","",E22)),"对","错")) -> 对
A23: 待R1-02 | B23: 前30 | C23: 顾客：上次买的收纳盒，想申请无理由退货。 客服：您这单系统显示已经超过七天了，不能退了。 顾客：我记得是上周才收到的。 客服：物流显示早就签收了，您可能记错了。 | D23: 待复核 | E23: R1 | F23: 《暂行办法》第十条 | G23: 一般 | I23: 缺的信息：具体签收日期，无法判断是否超过七日 | J23: 待复核 | K23: R1 | L23: =IF(J23="","",IF(AND(J23=D23,IF(K23="无","",K23)=IF(E23="","",E23)),"对","错")) -> 对
A24: 待R2-01 | B24: 前30 | C24: 顾客：这款空气炸锅耐用吗？ 客服：亲，我们家这款卖得特别好呢，月销三万多，好评率98%，基本没听说过坏的～ 顾客：那我放心了。 | D24: 待复核 | E24: R2 | F24: 《实施条例》第九条 | G24: 客气 | I24: 缺的信息：销量和好评率是否真实 | J24: 待复核 | K24: R2 | L24: =IF(J24="","",IF(AND(J24=D24,IF(K24="无","",K24)=IF(E24="","",E24)),"对","错")) -> 对
A25: 待R2-02 | B25: 后10 | C25: 顾客：这个儿童水杯材质安全吗？ 客服：亲，我们这款是食品级材质，有第三方检测报告的呢～ 顾客：能发我看看报告吗？ 客服：报告在仓库那边，我之后帮您问问，您先放心下单～ | D25: 待复核 | E25: R2 | F25: 《保护法》第二十条第一款、第八条 | G25: 客气 | I25: 缺的信息：检测报告是否真实存在 | J25: 待复核 | K25: R2 | L25: =IF(J25="","",IF(AND(J25=D25,IF(K25="无","",K25)=IF(E25="","",E25)),"对","错")) -> 对
A26: 待R3-01 | B26: 前30 | C26: 顾客：三天前提交的换货申请，一直没有消息。 客服：亲，我帮您催一下仓库哦～ 顾客：昨天你也这么说。 客服：亲，真的在帮您催了呢，请再耐心等等～ | D26: 待复核 | E26: R3 | F26: 《保护法》第五十六条第一款第（八）项；《实施条例》第四十四条第一款 | G26: 客气 | I26: 缺的信息：是否真的在催、仓库是否正常处理中，无法判断是否故意拖延 | J26: 待复核 | K26: R3 | L26: =IF(J26="","",IF(AND(J26=D26,IF(K26="无","",K26)=IF(E26="","",E26)),"对","错")) -> 对
A27: 待R3-02 | B27: 前30 | C27: 顾客：杯盖有点松，扣不紧，想换一个。 客服：这属于正常使用磨损，不属于质量问题，不能换。 顾客：我才用了一周，怎么会磨损？ 客服：我们这边判断是正常磨损，不换。 | D27: 待复核 | E27: R3 | F27: 《保护法》第二十四条 | G27: 一般 | I27: 缺的信息：商品实际状况（无照片或检测结果） | J27: 待复核 | K27: R3 | L27: =IF(J27="","",IF(AND(J27=D27,IF(K27="无","",K27)=IF(E27="","",E27)),"对","错")) -> 对
A28: 待R4-01 | B28: 前30 | C28: 顾客：吃了你们的零食肚子疼，你们得给个说法。 客服：非常抱歉。麻烦您提供一下就诊记录，我们好评估赔偿。 顾客：需要这个吗？ 客服：赔偿金额要依据就诊费用核算的。 | D28: 待复核 | E28: R4 | F28: 《实施条例》第二十三条第二款 | G28: 一般 | I28: 缺的信息：消费者是否主张医疗费用赔偿，无法判断收集是否必要 | J28: 合规 | L28: =IF(J28="","",IF(AND(J28=D28,IF(K28="无","",K28)=IF(E28="","",E28)),"对","错")) -> 错
A29: 合规-01 | B29: 前30 | C29: 顾客：面霜收到四天，想退货。 客服：亲，请问包装和封口膜是否完好呢？ 顾客：封口膜我撕开了，已经用了差不多四分之一瓶，觉得不适合我。 客服：亲，化妆品的封口膜属于必要的一次性密封包装，已经撕开并且用了不少，影响二次销售，这种情况不支持无理由退货哦～如果是质量问题，您可以拍照给我，我们再帮您处理。 | D29: 合规 | F29: 《暂行办法》第九条第（一）项 | G29: 客气 | H29: 难题 | I29: 拒绝退货有依据，看Agent会不会一律判R1 | J29: 合规 | L29: =IF(J29="","",IF(AND(J29=D29,IF(K29="无","",K29)=IF(E29="","",E29)),"对","错")) -> 对
A30: 合规-02 | B30: 后10 | C30: 顾客：我爸妈六十多了，关节不太好，这款鱼油有用吗？ 客服：亲，鱼油属于保健食品，不能代替药品哦。这款主要是日常营养补充，对叔叔阿姨有没有帮助因人而异。关节不舒服的话，建议先去医院检查一下。 顾客：好的，那我先买一瓶试试。 | D30: 合规 | F30: 未宣称功效，并提示不能替代药品 | G30: 一般 | H30: 难题 | I30: 关键词（老人、关节）敏感，但内容合规，看Agent会不会误报R2 | J30: 合规 | L30: =IF(J30="","",IF(AND(J30=D30,IF(K30="无","",K30)=IF(E30="","",E30)),"对","错")) -> 对
A31: 合规-03 | B31: 前30 | C31: 顾客：为什么买个海外的面膜还要填身份证？ 客服：亲，海外商品通过跨境渠道进口，清关时需要收件人实名信息哦～请在订单页的“实名信息”处填写就可以。证件照片请不要发在聊天里，注意保护隐私呢。 顾客：好的，我去填。 | D31: 合规 | F31: 无需引用条文（用于测试是否误报R4） | G31: 客气 | H31: 难题 | I31: 实名为清关所需，且客服提醒不要在聊天里发证件。真实平台流程由本人核对 | J31: 合规 | L31: =IF(J31="","",IF(AND(J31=D31,IF(K31="无","",K31)=IF(E31="","",E31)),"对","错")) -> 对
A32: 合规-04 | B32: 前30 | C32: 顾客：我下的单还没发货，想改一下收货地址。 客服：可以的，请把订单号、新的收货地址和收件人电话发我，我帮您修改。 顾客：好的，订单号××××，新地址××区××路8号，电话138××××0000。 客服：已修改成功，请核对。 | D32: 合规 | F32: 无需引用条文（用于测试是否误报R4） | G32: 一般 | H32: 难题 | I32: 新地址和电话是改地址必需的信息 | J32: 合规 | L32: =IF(J32="","",IF(AND(J32=D32,IF(K32="无","",K32)=IF(E32="","",E32)),"对","错")) -> 对
A33: 合规-05 | B33: 前30 | C33: 顾客：我第三次问了，退款什么时候到账？ 客服：已经回复过了，三到五个工作日，请耐心等待。 顾客：你们能不能快点？ 客服：流程就是这样，没法加急，请等待。 | D33: 合规 | F33: 无需引用条文（用于测试是否误报R5） | G33: 直白 | H33: 难题 | I33: 语气冷淡，但没有辱骂、讽刺或威胁，也给了明确答复 | J33: 合规 | L33: =IF(J33="","",IF(AND(J33=D33,IF(K33="无","",K33)=IF(E33="","",E33)),"对","错")) -> 对
A34: 合规-06 | B34: 前30 | C34: 顾客：退货申请提交了，多久能处理？ 客服：亲，一般三到五个工作日内会有审核结果哦～遇到活动高峰期可能会稍晚一点，有进展我会第一时间通知您。 顾客：好的。 | D34: 合规 | F34: 无需引用条文（用于测试是否误报R2、R3） | G34: 客气 | H34: 难题 | I34: “一般”的时间范围，并说明可能延后，不是绝对承诺 | J34: 合规 | L34: =IF(J34="","",IF(AND(J34=D34,IF(K34="无","",K34)=IF(E34="","",E34)),"对","错")) -> 对
A35: 合规-07 | B35: 前30 | C35: 顾客：我昨天收到的刻字水杯，不喜欢，想七天无理由退货。 客服：您好，请问这个杯子是您下单时自己提供刻字内容定制的吗？ 顾客：对，刻的是我名字。 客服：定制商品属于消费者定作的商品，依据规定不适用七日无理由退货，抱歉不能为您办理。如果杯子本身有质量问题，您拍照发我，我们会处理。 | D35: 合规 | F35: 《暂行办法》第六条第（一）项；《保护法》第二十五条第一款第（一）项 | G35: 一般 | H35: 难题 | I35: 拒绝有依据，还留了质量问题的途径 | J35: 合规 | L35: =IF(J35="","",IF(AND(J35=D35,IF(K35="无","",K35)=IF(E35="","",E35)),"对","错")) -> 对
A36: 合规-08 | B36: 前30 | C36: 顾客：用了两个月的保温杯，杯身凹了一块，想换一个新的。 客服：亲，请问是怎么凹的呢？ 顾客：前几天从桌上掉下来摔的。 客服：亲，这属于意外损坏，不属于质量问题，所以不能免费换新哦～如果您需要，我可以帮您转到付费维修，费用您看接受吗？ | D36: 合规 | F36: 《保护法》第二十四条（适用于商品不符合质量要求的情形） | G36: 客气 | H36: 难题 | I36: 顾客自己承认是摔的，拒绝有理由，看Agent会不会一律判R3 | J36: 合规 | L36: =IF(J36="","",IF(AND(J36=D36,IF(K36="无","",K36)=IF(E36="","",E36)),"对","错")) -> 对
A37: 合规-09 | B37: 前30 | C37: 顾客：运动裤尺码不合适，收到第三天，想无理由退货。 客服：可以的。请把裤子和吊牌、赠送的袜子一起寄回，退回的运费由您承担。退货地址：××区××路××号，联系人王先生，电话已在订单页展示，请保留好寄件凭证。 顾客：好的，什么时候退款？ 客服：收到退回商品并确认完好后，七天内原路退款。 | D37: 合规 | F37: 《暂行办法》第十一条、第十二条、第十三条、第十八条 | G37: 直白 | H37: 基础 | I37: 流程完整、说明准确的基础题 | J37: 合规 | L37: =IF(J37="","",IF(AND(J37=D37,IF(K37="无","",K37)=IF(E37="","",E37)),"对","错")) -> 对
A38: 合规-10 | B38: 后10 | C38: 顾客：（发了一张订单截图，截图里带着完整银行卡号）这是我的订单，你看下退款到哪了。 客服：亲，我看到截图里有完整的银行卡号呢，聊天里尽量不要发这类信息哦，我这边也不需要，您可以撤回一下～退款进度我已经查到了，原路退回，预计一到三个工作日到账。 顾客：好的，谢谢提醒。 | D38: 合规 | F38: 无需引用条文（用于测试是否误报R4） | G38: 客气 | H38: 难题 | I38: 对话里出现银行卡号，但客服没有索要，反而提醒 | J38: 合规 | L38: =IF(J38="","",IF(AND(J38=D38,IF(K38="无","",K38)=IF(E38="","",E38)),"对","错")) -> 对
A39: 合规-11 | B39: 后10 | C39: 顾客：你们这破店发货这么慢，是不是都是废物？ 客服：非常抱歉让您久等了。我帮您查一下，订单是10月20日付款、22日发出，目前在途中，预计明天送达。 顾客：少废话，慢死了。 客服：理解您着急，如果明天还没收到，您联系我，我优先帮您处理。 | D39: 合规 | F39: 无需引用条文（用于测试是否误报R5） | G39: 一般 | H39: 难题 | I39: 辱骂的是顾客，不是客服，客服一直礼貌回应 | J39: 合规 | L39: =IF(J39="","",IF(AND(J39=D39,IF(K39="无","",K39)=IF(E39="","",E39)),"对","错")) -> 对
A40: 合规-12 | B40: 前30 | C40: 顾客：我想开张发票，公司报销用。 客服：好的亲～麻烦提供一下发票抬头和纳税人识别号哦，我帮您申请开具。 顾客：抬头是××科技有限公司，税号91××××××××。 客服：收到，电子发票开好后会发到您的订单邮箱，请注意查收～ | D40: 合规 | F40: 无需引用条文（用于测试是否误报R4） | G40: 客气 | H40: 难题 | I40: 开票需要抬头和税号，属于必要信息 | J40: 合规 | L40: =IF(J40="","",IF(AND(J40=D40,IF(K40="无","",K40)=IF(E40="","",E40)),"对","错")) -> 对
...

Sheet 配比核对与指标
A1: 一、配比核对（公式自动统计）
A2: 标准答案 | B2: 前30 | C2: 后10 | D2: 合计 | E2: 计划合计 | F2: 是否一致
A3: 违规 | B3: =COUNTIFS(测试集!$D$2:$D$41,A3,测试集!$B$2:$B$41,"前30") -> 15 | C3: =COUNTIFS(测试集!$D$2:$D$41,A3,测试集!$B$2:$B$41,"后10") -> 5 | D3: =B3+C3 -> 20 | E3: 20 | F3: =IF(D3=E3,"一致","不一致") -> 一致
A4: 待复核 | B4: =COUNTIFS(测试集!$D$2:$D$41,A4,测试集!$B$2:$B$41,"前30") -> 6 | C4: =COUNTIFS(测试集!$D$2:$D$41,A4,测试集!$B$2:$B$41,"后10") -> 1 | D4: =B4+C4 -> 7 | E4: 7 | F4: =IF(D4=E4,"一致","不一致") -> 一致
A5: 合规 | B5: =COUNTIFS(测试集!$D$2:$D$41,A5,测试集!$B$2:$B$41,"前30") -> 9 | C5: =COUNTIFS(测试集!$D$2:$D$41,A5,测试集!$B$2:$B$41,"后10") -> 4 | D5: =B5+C5 -> 13 | E5: 13 | F5: =IF(D5=E5,"一致","不一致") -> 一致
A6: 合计 | B6: =SUM(B3:B5) -> 30 | C6: =SUM(C3:C5) -> 10 | D6: =SUM(D3:D5) -> 40 | E6: =SUM(E3:E5) -> 40 | F6: =IF(AND(B6=30,C6=10,D6=E6),"一致","不一致") -> 一致
A7: 说明：“计划合计”为手工填入的数字，来自文档4.1的配比方案（违规20、待复核7、合规13）；前30应为30段，后10应为10段。
A9: 二、评估指标（填完“测试集”黄色列后自动计算）
A10: 指标 | B10: 前30 | C10: 后10 | D10: 全部
A11: 违规召回率 | B11: =IF(COUNTIFS(测试集!$J$2:$J$41,"<>",测试集!$B$2:$B$41,"前30")=0,"未填",COUNTIFS(测试集!$D$2:$D$41,"违规",测试集!$L$2:$L$41,"对",测试集!$B$2:$B$41,"前30")/COUNTIFS(测试集!$D$2:$D$41,"违规",测试集!$B$2:$B$41,"前30")) -> 0.86666667 | C11: =IF(COUNTIFS(测试集!$J$2:$J$41,"<>",测试集!$B$2:$B$41,"后10")=0,"未填",COUNTIFS(测试集!$D$2:$D$41,"违规",测试集!$L$2:$L$41,"对",测试集!$B$2:$B$41,"后10")/COUNTIFS(测试集!$D$2:$D$41,"违规",测试集!$B$2:$B$41,"后10")) -> 0.8 | D11: =IF(COUNTIFS(测试集!$J$2:$J$41,"<>")=0,"未填",COUNTIFS(测试集!$D$2:$D$41,"违规",测试集!$L$2:$L$41,"对")/COUNTIFS(测试集!$D$2:$D$41,"违规")) -> 0.85
A12: 误判率 | B12: =IF(COUNTIFS(测试集!$J$2:$J$41,"<>",测试集!$B$2:$B$41,"前30")=0,"未填",COUNTIFS(测试集!$D$2:$D$41,"合规",测试集!$J$2:$J$41,"违规",测试集!$B$2:$B$41,"前30")/COUNTIFS(测试集!$D$2:$D$41,"合规",测试集!$B$2:$B$41,"前30")) -> 0 | C12: =IF(COUNTIFS(测试集!$J$2:$J$41,"<>",测试集!$B$2:$B$41,"后10")=0,"未填",COUNTIFS(测试集!$D$2:$D$41,"合规",测试集!$J$2:$J$41,"违规",测试集!$B$2:$B$41,"后10")/COUNTIFS(测试集!$D$2:$D$41,"合规",测试集!$B$2:$B$41,"后10")) -> 0 | D12: =IF(COUNTIFS(测试集!$J$2:$J$41,"<>")=0,"未填",COUNTIFS(测试集!$D$2:$D$41,"合规",测试集!$J$2:$J$41,"违规")/COUNTIFS(测试集!$D$2:$D$41,"合规")) -> 0
A13: 人工复核占比 | B13: =IF(COUNTIFS(测试集!$J$2:$J$41,"<>",测试集!$B$2:$B$41,"前30")=0,"未填",COUNTIFS(测试集!$J$2:$J$41,"待复核",测试集!$B$2:$B$41,"前30")/COUNTIFS(测试集!$B$2:$B$41,"前30")) -> 0.16666667 | C13: =IF(COUNTIFS(测试集!$J$2:$J$41,"<>",测试集!$B$2:$B$41,"后10")=0,"未填",COUNTIFS(测试集!$J$2:$J$41,"待复核",测试集!$B$2:$B$41,"后10")/COUNTIFS(测试集!$B$2:$B$41,"后10")) -> 0.2 | D13: =IF(COUNTIFS(测试集!$J$2:$J$41,"<>")=0,"未填",COUNTIFS(测试集!$J$2:$J$41,"待复核")/COUNTA(测试集!$B$2:$B$41)) -> 0.175
A14: 违规被判待复核（段） | B14: =IF(COUNTIFS(测试集!$J$2:$J$41,"<>",测试集!$B$2:$B$41,"前30")=0,"未填",COUNTIFS(测试集!$D$2:$D$41,"违规",测试集!$J$2:$J$41,"待复核",测试集!$B$2:$B$41,"前30")) -> 0 | C14: =IF(COUNTIFS(测试集!$J$2:$J$41,"<>",测试集!$B$2:$B$41,"后10")=0,"未填",COUNTIFS(测试集!$D$2:$D$41,"违规",测试集!$J$2:$J$41,"待复核",测试集!$B$2:$B$41,"后10")) -> 1 | D14: =IF(COUNTIFS(测试集!$J$2:$J$41,"<>")=0,"未填",COUNTIFS(测试集!$D$2:$D$41,"违规",测试集!$J$2:$J$41,"待复核")) -> 1
A15: 计算口径（与文档4.3一致）： · 违规召回率 = 违规对话中，结论为“违规”且类型正确（“是否判对”=对）的段数 ÷ 违规对话总段数 · 误判率 = 合规对话中，被判为“违规”的段数 ÷ 合规对话总段数 · 人工复核占比 = 结论为“待复核”的段数 ÷ 该组总段数 · 违规被判为“待复核”不计入召回，单独记录在第14行
A17: 三、怎么填
A18: 在“测试集”表里，只填黄色的四列：J（Agent结论，下拉选）、K（Agent类型，下拉选；合规的行选“无”，待复核的行选Agent给出的类型）、M（判错的行选错误归因）、N（备注）。“是否判对”（L列）自动计算，不要手填。 填写示例：某条违规对话，Agent判为“违规”且类型“R1”，则J选“违规”、K选“R1”。 先只填前30段；后10段等第一轮改进完成后再跑。 注意：标准答案由非法律专业人员依据法规文本和规则表确定，可能与专业判断有出入；对话为自编，措辞可能比真实场景更直白或更典型。
